<?xml version="1.0"?>
<robot xmlns:xacro="http://www.ros.org/wiki/xacro">

    <xacro:property name="base_length" value="0.6" />
    <xacro:property name="base_width" value="0.4" />
    <xacro:property name="base_height" value="0.2" />
    <xacro:property name="wheel_radius" value="0.1" />
    <xacro:property name="wheel_length" value="0.05" />

    <link name="base_footprint" />

    <link name="base_link">
        <visual>
            <geometry>
                <box size="${base_length} ${base_width} ${base_height}" />
            </geometry>
            <origin xyz="0 0 ${base_height / 2.0}" rpy="0 0 0" />
            <material name="blue" />
        </visual>
        <collision>
            <geometry>
                <box size="${base_length} ${base_width} ${base_height}" />
            </geometry>
            <origin xyz="0 0 ${base_height / 2.0}" rpy="0 0 0" />
        </collision>
        <inertial>
            <origin xyz="0 0 ${base_height / 2.0}" rpy="0 0 0"/>
            <mass value="5.0"/>
            <inertia
            ixx="0.1" ixy="0.0" ixz="0.0"
            iyy="0.1" iyz="0.0"
            izz="0.1"/>
        </inertial>
    </link>

    <xacro:macro name="wheel_link" params="prefix">
        <link name="${prefix}_wheel_link">
            <visual>
                <geometry>
                    <cylinder radius="${wheel_radius}" length="${wheel_length}" />
                </geometry>
                <origin xyz="0 0 0" rpy="${pi / 2.0} 0 0" />
                <material name="grey" />
            </visual>
            <collision>
                <geometry>
                    <cylinder radius="${wheel_radius}" length="${wheel_length}" />
                </geometry>
                <origin xyz="0 0 0" rpy="${pi / 2.0} 0 0" />
            </collision>
            <inertial>
                <origin xyz="0 0 0" rpy="0 0 0"/>
                <mass value="0.5"/>
                <inertia
                    ixx="0.001" ixy="0.0" ixz="0.0"
                    iyy="0.001" iyz="0.0"
                    izz="0.001"/>
            </inertial>
        </link>
    </xacro:macro>

    <xacro:wheel_link prefix="right" />
    <xacro:wheel_link prefix="left" />

    <link name="caster_wheel_link">
        <visual>
            <geometry>
                <sphere radius="${wheel_radius / 2.0}" />
            </geometry>
            <origin xyz="0 0 0" rpy="0 0 0" />
            <material name="grey" />
        </visual>
        <collision>
            <geometry>
                <sphere radius="${wheel_radius / 2.0}" />
            </geometry>
        </collision>
        <inertial>
            <origin xyz="0 0 0" rpy="0 0 0"/>
            <mass value="0.2"/>
            <inertia
                ixx="0.0005" ixy="0.0" ixz="0.0"
                iyy="0.0005" iyz="0.0"
                izz="0.0005"/>
        </inertial>
    </link>

    <joint name="base_joint" type="fixed">
        <parent link="base_footprint" />
        <child link="base_link" />
        <origin xyz="0 0 ${wheel_radius}" rpy="0 0 0"/>
    </joint>

    <joint name="base_right_wheel_joint" type="continuous">
        <parent link="base_link" />
        <child link="right_wheel_link" />
        <origin xyz="${-base_length / 4.0} ${-(base_width + wheel_length) / 2.0} 0" rpy="0 0 0" />
        <axis xyz="0 1 0" />
    </joint>

    <joint name="base_left_wheel_joint" type="continuous">
        <parent link="base_link" />
        <child link="left_wheel_link" />
        <origin xyz="${-base_length / 4.0} ${(base_width + wheel_length) / 2.0} 0" rpy="0 0 0" />
        <axis xyz="0 1 0" />
    </joint>

    <joint name="base_caster_wheel_joint" type="fixed">
        <parent link="base_link" />
        <child link="caster_wheel_link" />
        <origin xyz="${base_length / 3.0} 0 ${-wheel_radius / 2.0}" rpy="0 0 0" />
    </joint>


    <link name="camera_link">
        <visual>
            <geometry>
                <box size="0.05 0.05 0.05"/>
            </geometry>
            <material name="red"/>
        </visual>
        <collision>
            <geometry>
                <box size="0.05 0.05 0.05"/>
            </geometry>
        </collision>
        <inertial>
            <origin xyz="0 0 0" rpy="0 0 0"/>
            <mass value="0.1"/>
            <inertia
                ixx="0.0001" ixy="0.0" ixz="0.0"
                iyy="0.0001" iyz="0.0"
                izz="0.0001"/>
        </inertial>
    </link>


    <joint name="camera_joint" type="fixed">
        <parent link="lidar_link"/>
        <child link="camera_link"/>
        <origin xyz="0 0 0.12" rpy="0 0 0"/>
    </joint>

    <link name="lidar_link">
        <visual>
            <geometry>
                <cylinder radius="0.04" length="0.18"/>
            </geometry>
            <material name="red"/>
        </visual>
        <collision>
            <geometry>
                <cylinder radius="0.04" length="0.18"/>
            </geometry>
        </collision>
        <inertial>
            <origin xyz="0 0 0" rpy="0 0 0"/>
            <mass value="0.2"/>
            <inertia
                ixx="0.0002" ixy="0.0" ixz="0.0"
                iyy="0.0002" iyz="0.0"
                izz="0.0002"/>
        </inertial>
    </link>


    <joint name="lidar_joint" type="fixed">
        <parent link="base_link"/>
        <child link="lidar_link"/>
        <origin xyz="0 0 ${base_height+0.025}"/>
    </joint>

    <link name="imu_link">
        <collision>
            <geometry>
                <box size="0.02 0.02 0.01"/>
            </geometry>
        </collision>

        <inertial>
            <origin xyz="0 0 0" rpy="0 0 0"/>
            <mass value="0.05"/>
            <inertia
                ixx="0.00001" ixy="0.0" ixz="0.0"
                iyy="0.00001" iyz="0.0"
                izz="0.00001"/>
        </inertial>
    </link>

    <joint name="imu_joint" type="fixed">
        <parent link="base_link"/>
        <child link="imu_link"/>
        <origin xyz="0 0 ${base_height/2.0}"/>
    </joint>

    <gazebo reference="camera_link">
        <sensor name="camera" type="camera">
            <topic>/camera/image_raw</topic>
            <update_rate>15</update_rate>

            <camera>
                <horizontal_fov>1.047</horizontal_fov>

                <image>
                    <width>320</width>
                    <height>240</height>
                    <format>R8G8B8</format>
                </image>

                <clip>
                    <near>0.02</near>
                    <far>300</far>
                </clip>
            </camera>

            <always_on>true</always_on>
            <visualize>true</visualize>
        </sensor>
    </gazebo>

    <gazebo reference="lidar_link">    
        <sensor name="gpu_lidar" type="gpu_lidar">
            <always_on>true</always_on>
            <update_rate>10</update_rate>
            <visualize>true</visualize>
            <topic>scan</topic>             
            <lidar>
                <scan>
                    <horizontal>
                    <samples>360</samples>
                    <resolution>1</resolution>
                    <min_angle>-3.14159</min_angle>
                    <max_angle>3.14159</max_angle>
                    </horizontal>
                </scan>
                <range>
                    <min>0.08</min>
                    <max>10.0</max>
                    <resolution>0.01</resolution>
                </range>
            </lidar>
        </sensor>
    </gazebo>

    <gazebo reference="imu_link">
        <sensor name="imu_sensor" type="imu">
            <topic>/imu/data</topic>
            <always_on>true</always_on>
            <update_rate>100</update_rate>
            <visualize>true</visualize>
        </sensor>
    </gazebo>

    <gazebo>
        <plugin filename="ignition-gazebo-diff-drive-system" name="ignition::gazebo::systems::DiffDrive">
            <left_joint>base_left_wheel_joint</left_joint>
            <right_joint>base_right_wheel_joint</right_joint>
            <wheel_separation>0.45</wheel_separation>
            <wheel_radius>0.1</wheel_radius>
            <odom_publish_frequency>50</odom_publish_frequency>
            <topic>cmd_vel</topic>
            
            <publish_odom>true</publish_odom>
            <publish_odom_tf>true</publish_odom_tf>
            <publish_wheel_tf>true</publish_wheel_tf>
            
            <left_wheel_frame>left_wheel_link</left_wheel_frame>
            <right_wheel_frame>right_wheel_link</right_wheel_frame>
            
            <frame_id>odom</frame_id>
            <child_frame_id>base_footprint</child_frame_id> 
        </plugin>
    </gazebo>

    <gazebo reference="caster_wheel_link">
        <mu1>0.0</mu1>
        <mu2>0.0</mu2>
        <kp>1000000.0</kp>
        <kd>1.0</kd>
    </gazebo>

    <gazebo reference="left_wheel_link">
        <mu1>1.5</mu1>
        <mu2>1.5</mu2>
    </gazebo>

    <gazebo reference="right_wheel_link">
        <mu1>1.5</mu1>
        <mu2>1.5</mu2>
    </gazebo>





</robot>